Workbook
Name Slicer_Category: #N/A
Name Slicer_Months: #N/A
Name Slicer_Region: #N/A
Name Slicer_Ship_Mode: #N/A
Name Slicer_Status: #N/A
Name Slicer_year: #N/A

Sheet README
A1: Retail Sales Dataset (synthetic practice data - not real company data)
A3: Orders: 1,200 orders, Jan 2024 - Dec 2025. Sales and Profit are NOT given - you calculate them (Task L / F).
A4: Products: lookup table for Product Name, Category, Cost Price, Unit Price.
A5: Customers: lookup table for Customer Name, City, State, Region, Segment.
A6: Monthly_Targets_2025: wide format (months as columns) - use Power Query Unpivot.
A8: Formulas to use: Sales = Quantity x Unit Price x (1 - Discount) | Profit = Sales - (Quantity x Cost Price)
A9: Note: Returned / Cancelled orders should be excluded from Sales analysis (Status = Delivered or Pending only).

Sheet Orders
A1: Order ID | B1: Order Date | C1: Customer ID | D1: Month | E1: Product ID | F1: Quantity | G1: Discount | H1: Ship Mode | I1: Payment Mode | J1: Status | K1: unit_price | L1: cost_price | M1: net_sales | N1: total_cost | O1: profit | P1: discount_amount | Q1: Product Name | R1: Category | S1: State | T1: Region | U1: segment | V1: Months | W1: year
A2: ORD00001 | B2: 45293 | C2: C0032 | D2: =TEXT(Table1[[#This Row],[Order Date]],"mmmm") -> January | E2: P009 | F2: 4 | G2: 0.05 | H2: Express | I2: Cash on Delivery | J2: Delivered | K2: =VLOOKUP(E2,Products!$A$2:$E$23,5,0) -> 4299 | L2: =VLOOKUP(E2,Products!$A$2:$E$23,4,0) -> 2800 | M2: =K2*F2-Table1[[#This Row],[discount_amount]] -> 16336.2 | N2: =F2*L2 -> 11200 | O2: =M2-N2 -> 5136.2 | P2: =Table1[[#This Row],[Quantity]]*Table1[[#This Row],[unit_price]]*Table1[[#This Row],[Discount]] -> 859.8 | Q2: =VLOOKUP(E2,Products!$A$2:$E$23,2,0) -> Bookshelf | R2: =VLOOKUP(Table1[[#This Row],[Product ID]],Products!$A$2:$E$23,3,0) -> Furniture | S2: =VLOOKUP(C2,Customers!$A$2:$F$201,4,0) -> Madhya Pradesh | T2: =VLOOKUP(Table1[[#This Row],[Customer ID]],Customers!$A$2:$F$201,5,0) -> Central | U2: =VLOOKUP(Table1[[#This Row],[Customer ID]],Customers!$A$2:$F$201,6,0) -> Corporate | V2: =TEXT(Table1[[#This Row],[Order Date]],"MMM") -> Jan | W2: =TEXT(Table1[[#This Row],[Order Date]],"yyyy") -> 2024
A3: ORD00002 | B3: 45293 | C3: C0048 | D3: =TEXT(Table1[[#This Row],[Order Date]],"mmmm") -> January | E3: P011 | F3: 6 | G3: 0.1 | H3: Same Day | I3: Debit Card | J3: Delivered | K3: =VLOOKUP(E3,Products!$A$2:$E$23,5,0) -> 899 | L3: =VLOOKUP(E3,Products!$A$2:$E$23,4,0) -> 500 | M3: =K3*F3-Table1[[#This Row],[discount_amount]] -> 4854.6 | N3: =F3*L3 -> 3000 | O3: =M3-N3 -> 1854.6 | P3: =Table1[[#This Row],[Quantity]]*Table1[[#This Row],[unit_price]]*Table1[[#This Row],[Discount]] -> 539.4 | Q3: =VLOOKUP(E3,Products!$A$2:$E$23,2,0) -> Monitor Stand | R3: =VLOOKUP(Table1[[#This Row],[Product ID]],Products!$A$2:$E$23,3,0) -> Furniture | S3: =VLOOKUP(C3,Customers!$A$2:$F$201,4,0) -> Gujarat | T3: =VLOOKUP(Table1[[#This Row],[Customer ID]],Customers!$A$2:$F$201,5,0) -> West | U3: =VLOOKUP(Table1[[#This Row],[Customer ID]],Customers!$A$2:$F$201,6,0) -> Consumer | V3: =TEXT(Table1[[#This Row],[Order Date]],"MMM") -> Jan | W3: =TEXT(Table1[[#This Row],[Order Date]],"yyyy") -> 2024
A4: ORD00003 | B4: 45294 | C4: C0187 | D4: =TEXT(Table1[[#This Row],[Order Date]],"mmmm") -> January | E4: P003 | F4: 5 | G4: 0 | H4: Standard | I4: Net Banking | J4: Delivered | K4: =VLOOKUP(E4,Products!$A$2:$E$23,5,0) -> 599 | L4: =VLOOKUP(E4,Products!$A$2:$E$23,4,0) -> 350 | M4: =K4*F4-Table1[[#This Row],[discount_amount]] -> 2995 | N4: =F4*L4 -> 1750 | O4: =M4-N4 -> 1245 | P4: =Table1[[#This Row],[Quantity]]*Table1[[#This Row],[unit_price]]*Table1[[#This Row],[Discount]] -> 0 | Q4: =VLOOKUP(E4,Products!$A$2:$E$23,2,0) -> USB Flash Drive 64GB | R4: =VLOOKUP(Table1[[#This Row],[Product ID]],Products!$A$2:$E$23,3,0) -> Electronics | S4: =VLOOKUP(C4,Customers!$A$2:$F$201,4,0) -> Maharashtra | T4: =VLOOKUP(Table1[[#This Row],[Customer ID]],Customers!$A$2:$F$201,5,0) -> West | U4: =VLOOKUP(Table1[[#This Row],[Customer ID]],Customers!$A$2:$F$201,6,0) -> Consumer | V4: =TEXT(Table1[[#This Row],[Order Date]],"MMM") -> Jan | W4: =TEXT(Table1[[#This Row],[Order Date]],"yyyy") -> 2024
A5: ORD00004 | B5: 45294 | C5: C0083 | D5: =TEXT(Table1[[#This Row],[Order Date]],"mmmm") -> January | E5: P010 | F5: 1 | G5: 0 | H5: Express | I5: Cash on Delivery | J5: Delivered | K5: =VLOOKUP(E5,Products!$A$2:$E$23,5,0) -> 4599 | L5: =VLOOKUP(E5,Products!$A$2:$E$23,4,0) -> 3000 | M5: =K5*F5-Table1[[#This Row],[discount_amount]] -> 4599 | N5: =F5*L5 -> 3000 | O5: =M5-N5 -> 1599 | P5: =Table1[[#This Row],[Quantity]]*Table1[[#This Row],[unit_price]]*Table1[[#This Row],[Discount]] -> 0 | Q5: =VLOOKUP(E5,Products!$A$2:$E$23,2,0) -> Filing Cabinet | R5: =VLOOKUP(Table1[[#This Row],[Product ID]],Products!$A$2:$E$23,3,0) -> Furniture | S5: =VLOOKUP(C5,Customers!$A$2:$F$201,4,0) -> West Bengal | T5: =VLOOKUP(Table1[[#This Row],[Customer ID]],Customers!$A$2:$F$201,5,0) -> East | U5: =VLOOKUP(Table1[[#This Row],[Customer ID]],Customers!$A$2:$F$201,6,0) -> Consumer | V5: =TEXT(Table1[[#This Row],[Order Date]],"MMM") -> Jan | W5: =TEXT(Table1[[#This Row],[Order Date]],"yyyy") -> 2024
A6: ORD00005 | B6: 45294 | C6: C0184 | D6: =TEXT(Table1[[#This Row],[Order Date]],"mmmm") -> January | E6: P020 | F6: 5 | G6: 0 | H6: Express | I6: UPI | J6: Delivered | K6: =VLOOKUP(E6,Products!$A$2:$E$23,5,0) -> 1799 | L6: =VLOOKUP(E6,Products!$A$2:$E$23,4,0) -> 900 | M6: =K6*F6-Table1[[#This Row],[discount_amount]] -> 8995 | N6: =F6*L6 -> 4500 | O6: =M6-N6 -> 4495 | P6: =Table1[[#This Row],[Quantity]]*Table1[[#This Row],[unit_price]]*Table1[[#This Row],[Discount]] -> 0 | Q6: =VLOOKUP(E6,Products!$A$2:$E$23,2,0) -> Denim Jeans | R6: =VLOOKUP(Table1[[#This Row],[Product ID]],Products!$A$2:$E$23,3,0) -> Clothing | S6: =VLOOKUP(C6,Customers!$A$2:$F$201,4,0) -> Gujarat | T6: =VLOOKUP(Table1[[#This Row],[Customer ID]],Customers!$A$2:$F$201,5,0) -> West | U6: =VLOOKUP(Table1[[#This Row],[Customer ID]],Customers!$A$2:$F$201,6,0) -> Consumer | V6: =TEXT(Table1[[#This Row],[Order Date]],"MMM") -> Jan | W6: =TEXT(Table1[[#This Row],[Order Date]],"yyyy") -> 2024
A7: ORD00006 | B7: 45297 | C7: C0158 | D7: =TEXT(Table1[[#This Row],[Order Date]],"mmmm") -> January | E7: P012 | F7: 5 | G7: 0 | H7: Standard | I7: UPI | J7: Pending | K7: =VLOOKUP(E7,Products!$A$2:$E$23,5,0) -> 320 | L7: =VLOOKUP(E7,Products!$A$2:$E$23,4,0) -> 220 | M7: =K7*F7-Table1[[#This Row],[discount_amount]] -> 1600 | N7: =F7*L7 -> 1100 | O7: =M7-N7 -> 500 | P7: =Table1[[#This Row],[Quantity]]*Table1[[#This Row],[unit_price]]*Table1[[#This Row],[Discount]] -> 0 | Q7: =VLOOKUP(E7,Products!$A$2:$E$23,2,0) -> A4 Paper Ream | R7: =VLOOKUP(Table1[[#This Row],[Product ID]],Products!$A$2:$E$23,3,0) -> Office Supplies | S7: =VLOOKUP(C7,Customers!$A$2:$F$201,4,0) -> Telangana | T7: =VLOOKUP(Table1[[#This Row],[Customer ID]],Customers!$A$2:$F$201,5,0) -> South | U7: =VLOOKUP(Table1[[#This Row],[Customer ID]],Customers!$A$2:$F$201,6,0) -> Corporate | V7: =TEXT(Table1[[#This Row],[Order Date]],"MMM") -> Jan | W7: =TEXT(Table1[[#This Row],[Order Date]],"yyyy") -> 2024
A8: ORD00007 | B8: 45298 | C8: C0164 | D8: =TEXT(Table1[[#This Row],[Order Date]],"mmmm") -> January | E8: P022 | F8: 5 | G8: 0 | H8: Same Day | I8: Credit Card | J8: Delivered | K8: =VLOOKUP(E8,Products!$A$2:$E$23,5,0) -> 899 | L8: =VLOOKUP(E8,Products!$A$2:$E$23,4,0) -> 450 | M8: =K8*F8-Table1[[#This Row],[discount_amount]] -> 4495 | N8: =F8*L8 -> 2250 | O8: =M8-N8 -> 2245 | P8: =Table1[[#This Row],[Quantity]]*Table1[[#This Row],[unit_price]]*Table1[[#This Row],[Discount]] -> 0 | Q8: =VLOOKUP(E8,Products!$A$2:$E$23,2,0) -> Track Pants | R8: =VLOOKUP(Table1[[#This Row],[Product ID]],Products!$A$2:$E$23,3,0) -> Clothing | S8: =VLOOKUP(C8,Customers!$A$2:$F$201,4,0) -> Gujarat | T8: =VLOOKUP(Table1[[#This Row],[Customer ID]],Customers!$A$2:$F$201,5,0) -> West | U8: =VLOOKUP(Table1[[#This Row],[Customer ID]],Customers!$A$2:$F$201,6,0) -> Home Office | V8: =TEXT(Table1[[#This Row],[Order Date]],"MMM") -> Jan | W8: =TEXT(Table1[[#This Row],[Order Date]],"yyyy") -> 2024
A9: ORD00008 | B9: 45299 | C9: C0037 | D9: =TEXT(Table1[[#This Row],[Order Date]],"mmmm") -> January | E9: P001 | F9: 6 | G9: 0 | H9: Same Day | I9: Debit Card | J9: Delivered | K9: =VLOOKUP(E9,Products!$A$2:$E$23,5,0) -> 700 | L9: =VLOOKUP(E9,Products!$A$2:$E$23,4,0) -> 450 | M9: =K9*F9-Table1[[#This Row],[discount_amount]] -> 4200 | N9: =F9*L9 -> 2700 | O9: =M9-N9 -> 1500 | P9: =Table1[[#This Row],[Quantity]]*Table1[[#This Row],[unit_price]]*Table1[[#This Row],[Discount]] -> 0 | Q9: =VLOOKUP(E9,Products!$A$2:$E$23,2,0) -> Wireless Mouse | R9: =VLOOKUP(Table1[[#This Row],[Product ID]],Products!$A$2:$E$23,3,0) -> Electronics | S9: =VLOOKUP(C9,Customers!$A$2:$F$201,4,0) -> Maharashtra | T9: =VLOOKUP(Table1[[#This Row],[Customer ID]],Customers!$A$2:$F$201,5,0) -> West | U9: =VLOOKUP(Table1[[#This Row],[Customer ID]],Customers!$A$2:$F$201,6,0) -> Home Office | V9: =TEXT(Table1[[#This Row],[Order Date]],"MMM") -> Jan | W9: =TEXT(Table1[[#This Row],[Order Date]],"yyyy") -> 2024
A10: ORD00009 | B10: 45299 | C10: C0099 | D10: =TEXT(Table1[[#This Row],[Order Date]],"mmmm") -> January | E10: P012 | F10: 1 | G10: 0.05 | H10: Express | I10: Debit Card | J10: Delivered | K10: =VLOOKUP(E10,Products!$A$2:$E$23,5,0) -> 320 | L10: =VLOOKUP(E10,Products!$A$2:$E$23,4,0) -> 220 | M10: =K10*F10-Table1[[#This Row],[discount_amount]] -> 304 | N10: =F10*L10 -> 220 | O10: =M10-N10 -> 84 | P10: =Table1[[#This Row],[Quantity]]*Table1[[#This Row],[unit_price]]*Table1[[#This Row],[Discount]] -> 16 | Q10: =VLOOKUP(E10,Products!$A$2:$E$23,2,0) -> A4 Paper Ream | R10: =VLOOKUP(Table1[[#This Row],[Product ID]],Products!$A$2:$E$23,3,0) -> Office Supplies | S10: =VLOOKUP(C10,Customers!$A$2:$F$201,4,0) -> Kerala | T10: =VLOOKUP(Table1[[#This Row],[Customer ID]],Customers!$A$2:$F$201,5,0) -> South | U10: =VLOOKUP(Table1[[#This Row],[Customer ID]],Customers!$A$2:$F$201,6,0) -> Consumer | V10: =TEXT(Table1[[#This Row],[Order Date]],"MMM") -> Jan | W10: =TEXT(Table1[[#This Row],[Order Date]],"yyyy") -> 2024
A11: ORD00010 | B11: 45300 | C11: C0196 | D11: =TEXT(Table1[[#This Row],[Order Date]],"mmmm") -> January | E11: P015 | F11: 1 | G11: 0.05 | H11: Express | I11: Debit Card | J11: Delivered | K11: =VLOOKUP(E11,Products!$A$2:$E$23,5,0) -> 299 | L11: =VLOOKUP(E11,Products!$A$2:$E$23,4,0) -> 180 | M11: =K11*F11-Table1[[#This Row],[discount_amount]] -> 284.05 | N11: =F11*L11 -> 180 | O11: =M11-N11 -> 104.05 | P11: =Table1[[#This Row],[Quantity]]*Table1[[#This Row],[unit_price]]*Table1[[#This Row],[Discount]] -> 14.95 | Q11: =VLOOKUP(E11,Products!$A$2:$E$23,2,0) -> Notebook Pack of 5 | R11: =VLOOKUP(Table1[[#This Row],[Product ID]],Products!$A$2:$E$23,3,0) -> Office Supplies | S11: =VLOOKUP(C11,Customers!$A$2:$F$201,4,0) -> Madhya Pradesh | T11: =VLOOKUP(Table1[[#This Row],[Customer ID]],Customers!$A$2:$F$201,5,0) -> Central | U11: =VLOOKUP(Table1[[#This Row],[Customer ID]],Customers!$A$2:$F$201,6,0) -> Corporate | V11: =TEXT(Table1[[#This Row],[Order Date]],"MMM") -> Jan | W11: =TEXT(Table1[[#This Row],[Order Date]],"yyyy") -> 2024
A12: ORD00011 | B12: 45301 | C12: C0072 | D12: =TEXT(Table1[[#This Row],[Order Date]],"mmmm") -> January | E12: P021 | F12: 2 | G12: 0.2 | H12: Standard | I12: Cash on Delivery | J12: Delivered | K12: =VLOOKUP(E12,Products!$A$2:$E$23,5,0) -> 1599 | L12: =VLOOKUP(E12,Products!$A$2:$E$23,4,0) -> 800 | M12: =K12*F12-Table1[[#This Row],[discount_amount]] -> 2558.4 | N12: =F12*L12 -> 1600 | O12: =M12-N12 -> 958.4 | P12: =Table1[[#This Row],[Quantity]]*Table1[[#This Row],[unit_price]]*Table1[[#This Row],[Discount]] -> 639.6 | Q12: =VLOOKUP(E12,Products!$A$2:$E$23,2,0) -> Hoodie | R12: =VLOOKUP(Table1[[#This Row],[Product ID]],Products!$A$2:$E$23,3,0) -> Clothing | S12: =VLOOKUP(C12,Customers!$A$2:$F$201,4,0) -> Maharashtra | T12: =VLOOKUP(Table1[[#This Row],[Customer ID]],Customers!$A$2:$F$201,5,0) -> West | U12: =VLOOKUP(Table1[[#This Row],[Customer ID]],Customers!$A$2:$F$201,6,0) -> Consumer | V12: =TEXT(Table1[[#This Row],[Order Date]],"MMM") -> Jan | W12: =TEXT(Table1[[#This Row],[Order Date]],"yyyy") -> 2024
A13: ORD00012 | B13: 45304 | C13: C0100 | D13: =TEXT(Table1[[#This Row],[Order Date]],"mmmm") -> January | E13: P017 | F13: 10 | G13: 0 | H13: Same Day | I13: Cash on Delivery | J13: Delivered | K13: =VLOOKUP(E13,Products!$A$2:$E$23,5,0) -> 449 | L13: =VLOOKUP(E13,Products!$A$2:$E$23,4,0) -> 260 | M13: =K13*F13-Table1[[#This Row],[discount_amount]] -> 4490 | N13: =F13*L13 -> 2600 | O13: =M13-N13 -> 1890 | P13: =Table1[[#This Row],[Quantity]]*Table1[[#This Row],[unit_price]]*Table1[[#This Row],[Discount]] -> 0 | Q13: =VLOOKUP(E13,Products!$A$2:$E$23,2,0) -> Desk Organizer | R13: =VLOOKUP(Table1[[#This Row],[Product ID]],Products!$A$2:$E$23,3,0) -> Office Supplies | S13: =VLOOKUP(C13,Customers!$A$2:$F$201,4,0) -> Rajasthan | T13: =VLOOKUP(Table1[[#This Row],[Customer ID]],Customers!$A$2:$F$201,5,0) -> North | U13: =VLOOKUP(Table1[[#This Row],[Customer ID]],Customers!$A$2:$F$201,6,0) -> Corporate | V13: =TEXT(Table1[[#This Row],[Order Date]],"MMM") -> Jan | W13: =TEXT(Table1[[#This Row],[Order Date]],"yyyy") -> 2024
... A1201: ORD01200 | B1201: 46021 | C1201: C0028 | D1201: =TEXT(Table1[[#This Row],[Order Date]],"mmmm") -> December | E1201: P009 | F1201: 12 | G1201: 0.1 | H1201: Same Day | I1201: Cash on Delivery | J1201: Delivered | K1201: =VLOOKUP(E1201,Products!$A$2:$E$23,5,0) -> 4299 | L1201: =VLOOKUP(E1201,Products!$A$2:$E$23,4,0) -> 2800 | M1201: =K1201*F1201-Table1[[#This Row],[discount_amount]] -> 46429.2 | N1201: =F1201*L1201 -> 33600 | O1201: =M1201-N1201 -> 12829.2 | P1201: =Table1[[#This Row],[Quantity]]*Table1[[#This Row],[unit_price]]*Table1[[#This Row],[Discount]] -> 5158.8 | Q1201: =VLOOKUP(E1201,Products!$A$2:$E$23,2,0) -> Bookshelf | R1201: =VLOOKUP(Table1[[#This Row],[Product ID]],Products!$A$2:$E$23,3,0) -> Furniture | S1201: =VLOOKUP(C1201,Customers!$A$2:$F$201,4,0) -> Gujarat | T1201: =VLOOKUP(Table1[[#This Row],[Customer ID]],Customers!$A$2:$F$201,5,0) -> West | U1201: =VLOOKUP(Table1[[#This Row],[Customer ID]],Customers!$A$2:$F$201,6,0) -> Consumer | V1201: =TEXT(Table1[[#This Row],[Order Date]],"MMM") -> Dec | W1201: =TEXT(Table1[[#This Row],[Order Date]],"yyyy") -> 2025

Sheet Products
A1: Product ID | B1: Product Name | C1: Category | D1: Cost Price (INR) | E1: Unit Price (INR)
A2: P001 | B2: Wireless Mouse | C2: Electronics | D2: 450 | E2: 700
A3: P002 | B3: Bluetooth Speaker | C3: Electronics | D3: 1200 | E3: 1999
A4: P003 | B4: USB Flash Drive 64GB | C4: Electronics | D4: 350 | E4: 599
A5: P004 | B5: Headphones | C5: Electronics | D5: 900 | E5: 1599
A6: P005 | B6: Power Bank 10000mAh | C6: Electronics | D6: 800 | E6: 1299
A7: P006 | B7: Webcam HD | C7: Electronics | D7: 1100 | E7: 1799
A8: P007 | B8: Office Chair | C8: Furniture | D8: 3500 | E8: 5499
A9: P008 | B9: Study Table | C9: Furniture | D9: 4200 | E9: 6499
A10: P009 | B10: Bookshelf | C10: Furniture | D10: 2800 | E10: 4299
A11: P010 | B11: Filing Cabinet | C11: Furniture | D11: 3000 | E11: 4599
A12: P011 | B12: Monitor Stand | C12: Furniture | D12: 500 | E12: 899
A13: P012 | B13: A4 Paper Ream | C13: Office Supplies | D13: 220 | E13: 320
... A23: P022 | B23: Track Pants | C23: Clothing | D23: 450 | E23: 899

Sheet Customers
A1: Customer ID | B1: Customer Name | C1: City | D1: State | E1: Region | F1: Segment
A2: C0001 | B2: Aarav Joshi | C2: Rajkot | D2: Gujarat | E2: West | F2: Consumer
A3: C0002 | B3: Rohan Joshi | C3: Jaipur | D3: Rajasthan | E3: North | F3: Consumer
A4: C0003 | B4: Aditya Nair | C4: Bhopal | D4: Madhya Pradesh | E4: Central | F4: Consumer
A5: C0004 | B5: Aditya Desai | C5: Ahmedabad | D5: Gujarat | E5: West | F5: Consumer
A6: C0005 | B6: Aarav Reddy | C6: Nagpur | D6: Maharashtra | E6: Central | F6: Consumer
A7: C0006 | B7: Kavya Desai | C7: Bhopal | D7: Madhya Pradesh | E7: Central | F7: Consumer
A8: C0007 | B8: Aarav Trivedi | C8: Chandigarh | D8: Chandigarh | E8: North | F8: Corporate
A9: C0008 | B9: Priya Sharma | C9: Kochi | D9: Kerala | E9: South | F9: Consumer
A10: C0009 | B10: Krish Shah | C10: Bengaluru | D10: Karnataka | E10: South | F10: Consumer
A11: C0010 | B11: Ananya Nair | C11: Chennai | D11: Tamil Nadu | E11: South | F11: Consumer
A12: C0011 | B12: Neha Reddy | C12: Surat | D12: Gujarat | E12: West | F12: Consumer
... A201: C0200 | B201: Divya Trivedi | C201: Chandigarh | D201: Chandigarh | E201: North | F201: Consumer

Sheet Sheet3
A1: Order ID | B1: Order Date | C1: Customer ID | D1: Month | E1: Product ID | F1: Quantity | G1: Discount | H1: Ship Mode | I1: Payment Mode | J1: Status | K1: unit_price | L1: cost_price | M1: net_sales | N1: total_cost | O1: profit | P1: discount_amount | Q1: Product Name | R1: Category | S1: State | T1: Region | U1: segment | V1: Months | W1: year
A2: ORD01172 | B2: 46002 | C2: C0131 | D2: December | E2: P018 | F2: 4 | G2: 0 | H2: Standard | I2: UPI | J2: Delivered | K2: 499 | L2: 250 | M2: 1996 | N2: 1000 | O2: 996 | P2: 0 | Q2: Cotton T-Shirt | R2: Clothing | S2: Odisha | T2: East | U2: Corporate | V2: Dec | W2: 2025
A3: ORD01152 | B3: 45990 | C3: C0101 | D3: November | E3: P018 | F3: 4 | G3: 0.1 | H3: Express | I3: Cash on Delivery | J3: Pending | K3: 499 | L3: 250 | M3: 1796.4 | N3: 1000 | O3: 796.4 | P3: 199.6 | Q3: Cotton T-Shirt | R3: Clothing | S3: Kerala | T3: South | U3: Corporate | V3: Nov | W3: 2025
A4: ORD01146 | B4: 45986 | C4: C0118 | D4: November | E4: P018 | F4: 4 | G4: 0.1 | H4: Standard | I4: Cash on Delivery | J4: Delivered | K4: 499 | L4: 250 | M4: 1796.4 | N4: 1000 | O4: 796.4 | P4: 199.6 | Q4: Cotton T-Shirt | R4: Clothing | S4: Karnataka | T4: South | U4: Corporate | V4: Nov | W4: 2025
A5: ORD01074 | B5: 45950 | C5: C0032 | D5: October | E5: P018 | F5: 4 | G5: 0.1 | H5: Express | I5: Cash on Delivery | J5: Delivered | K5: 499 | L5: 250 | M5: 1796.4 | N5: 1000 | O5: 796.4 | P5: 199.6 | Q5: Cotton T-Shirt | R5: Clothing | S5: Madhya Pradesh | T5: Central | U5: Corporate | V5: Oct | W5: 2025
A6: ORD01039 | B6: 45932 | C6: C0097 | D6: October | E6: P018 | F6: 4 | G6: 0.05 | H6: Standard | I6: UPI | J6: Pending | K6: 499 | L6: 250 | M6: 1896.2 | N6: 1000 | O6: 896.2 | P6: 99.8 | Q6: Cotton T-Shirt | R6: Clothing | S6: Gujarat | T6: West | U6: Corporate | V6: Oct | W6: 2025
A7: ORD00997 | B7: 45909 | C7: C0008 | D7: September | E7: P018 | F7: 6 | G7: 0.1 | H7: Express | I7: Net Banking | J7: Delivered | K7: 499 | L7: 250 | M7: 2694.6 | N7: 1500 | O7: 1194.6 | P7: 299.4 | Q7: Cotton T-Shirt | R7: Clothing | S7: Kerala | T7: South | U7: Consumer | V7: Sep | W7: 2025
A8: ORD00984 | B8: 45902 | C8: C0151 | D8: September | E8: P018 | F8: 1 | G8: 0 | H8: Standard | I8: Debit Card | J8: Delivered | K8: 499 | L8: 250 | M8: 499 | N8: 250 | O8: 249 | P8: 0 | Q8: Cotton T-Shirt | R8: Clothing | S8: Madhya Pradesh | T8: Central | U8: Consumer | V8: Sep | W8: 2025
A9: ORD00933 | B9: 45870 | C9: C0011 | D9: August | E9: P018 | F9: 10 | G9: 0 | H9: Standard | I9: Debit Card | J9: Delivered | K9: 499 | L9: 250 | M9: 4990 | N9: 2500 | O9: 2490 | P9: 0 | Q9: Cotton T-Shirt | R9: Clothing | S9: Gujarat | T9: West | U9: Consumer | V9: Aug | W9: 2025
A10: ORD00851 | B10: 45813 | C10: C0109 | D10: June | E10: P018 | F10: 6 | G10: 0.1 | H10: Standard | I10: Debit Card | J10: Cancelled | K10: 499 | L10: 250 | M10: 2694.6 | N10: 1500 | O10: 1194.6 | P10: 299.4 | Q10: Cotton T-Shirt | R10: Clothing | S10: Chandigarh | T10: North | U10: Consumer | V10: Jun | W10: 2025
A11: ORD00802 | B11: 45782 | C11: C0185 | D11: May | E11: P018 | F11: 1 | G11: 0 | H11: Express | I11: Debit Card | J11: Delivered | K11: 499 | L11: 250 | M11: 499 | N11: 250 | O11: 249 | P11: 0 | Q11: Cotton T-Shirt | R11: Clothing | S11: West Bengal | T11: East | U11: Corporate | V11: May | W11: 2025
A12: ORD00755 | B12: 45756 | C12: C0074 | D12: April | E12: P018 | F12: 2 | G12: 0.2 | H12: Same Day | I12: Credit Card | J12: Delivered | K12: 499 | L12: 250 | M12: 798.4 | N12: 500 | O12: 298.4 | P12: 199.6 | Q12: Cotton T-Shirt | R12: Clothing | S12: Madhya Pradesh | T12: Central | U12: Corporate | V12: Apr | W12: 2025
A13: ORD00742 | B13: 45751 | C13: C0182 | D13: April | E13: P018 | F13: 2 | G13: 0 | H13: Same Day | I13: UPI | J13: Delivered | K13: 499 | L13: 250 | M13: 998 | N13: 500 | O13: 498 | P13: 0 | Q13: Cotton T-Shirt | R13: Clothing | S13: Madhya Pradesh | T13: Central | U13: Consumer | V13: Apr | W13: 2025
... A43: ORD00065 | B43: 45338 | C43: C0190 | D43: February | E43: P018 | F43: 1 | G43: 0.15 | H43: Standard | I43: UPI | J43: Delivered | K43: 499 | L43: 250 | M43: 424.15 | N43: 250 | O43: 174.15 | P43: 74.85 | Q43: Cotton T-Shirt | R43: Clothing | S43: Delhi | T43: North | U43: Corporate | V43: Feb | W43: 2024

Sheet pivot_table
A1: Row Labels | B1: Sum of profit | C1: Sum of net_sales | D1: Row Labels | E1: Count of Order ID | G1: Row Labels | H1: Sum of profit | I1: Row Labels | J1: Count of Order ID | L1: Row Labels | M1: Count of Order ID
A2: Jan | B2: 217851.55 | C2: 595921.55 | D2: Cash on Delivery | E2: 242 | G2: Consumer | H2: 1614174.8 | I2: Cancelled | J2: 67 | L2: Uttar Pradesh | M2: 37
A3: Feb | B3: 141957.55 | C3: 406277.55 | D3: Credit Card | E3: 219 | G3: Corporate | H3: 754055.75 | I3: Delivered | J3: 1001 | L3: Karnataka | M3: 38
A4: Mar | B4: 279373.35 | C4: 750483.35 | D4: Debit Card | E4: 246 | G4: Home Office | H4: 349799.2 | I4: Pending | J4: 49 | L4: Odisha | M4: 57
A5: Apr | B5: 222276.6 | C5: 626176.6 | D5: Net Banking | E5: 241 | G5: Grand Total | H5: 2718029.7 | I5: Returned | J5: 83 | L5: Rajasthan | M5: 57
A6: May | B6: 252334.45 | C6: 716064.45 | D6: UPI | E6: 252 | I6: Grand Total | J6: 1200 | L6: Bihar | M6: 62
A7: Jun | B7: 160152.5 | C7: 437662.5 | D7: Grand Total | E7: 1200 | G7: Count of Order ID | L7: Tamil Nadu | M7: 63
A8: Jul | B8: 184184.9 | C8: 522634.9 | G8: 1200 | L8: West Bengal | M8: 64
A9: Aug | B9: 180688.3 | C9: 512178.3 | D9: Row Labels | E9: Sum of profit | F9: Sum of net_sales | G9: Row Labels | H9: Sum of profit | I9: Sum of net_sales | L9: Kerala | M9: 67
A10: Sep | B10: 204758.65 | C10: 607238.65 | D10: A4 Paper Ream | E10: 16136 | F10: 59696 | G10: Bihar | H10: 117282.75 | I10: 305792.75 | L10: Telangana | M10: 71
A11: Oct | B11: 267305.55 | C11: 764125.55 | D11: Bluetooth Speaker | E11: 109449.2 | F11: 301449.2 | G11: Chandigarh | H11: 152129.95 | I11: 419519.95 | L11: Chandigarh | M11: 77
A12: Nov | B12: 307084 | C12: 877914 | D12: Bookshelf | E12: 225478.15 | F12: 760278.15 | G12: Delhi | H12: 205561.25 | I12: 586581.25 | L12: Delhi | M12: 82
A13: Dec | B13: 300062.3 | C13: 908992.3 | D13: Cotton T-Shirt | E13: 35450.3 | F13: 74700.3 | G13: Gujarat | H13: 565493.8 | I13: 1636443.8 | L13: Maharashtra | M13: 142
A14: Grand Total | B14: 2718029.7 | C14: 7725669.7 | D14: Denim Jeans | E14: 174206.6 | F14: 383906.6 | G14: Karnataka | H14: 90663.8 | I14: 306053.8 | L14: Madhya Pradesh | M14: 148
D15: Desk Organizer | E15: 58419.9 | F15: 150459.9 | G15: Kerala | H15: 137398.7 | I15: 379428.7 | L15: Gujarat | M15: 235
D16: Filing Cabinet | E16: 345615.9 | F16: 1122615.9 | G16: Madhya Pradesh | H16: 351407.35 | I16: 993437.35 | L16: Grand Total | M16: 1200
A17: Row Labels | B17: Sum of profit | D17: Formal Shirt | E17: 149728.5 | F17: 325528.5 | G17: Maharashtra | H17: 308615.25 | I17: 922835.25
A18: Clothing | B18: 605436.8 | D18: Gel Pen Box | E18: 9382.5 | F18: 25852.5 | G18: Odisha | H18: 155017.8 | I18: 418357.8
A19: Electronics | B19: 587290.9 | D19: Headphones | E19: 164537.25 | F19: 420137.25 | G19: Rajasthan | H19: 139437.35 | I19: 382367.35
A20: Furniture | B20: 1380015.8 | D20: Hoodie | E20: 139251.85 | F20: 300851.85 | G20: Tamil Nadu | H20: 153041.1 | I20: 438531.1 | L20: Sum of profit | M20: Sum of net_sales
A21: Office Supplies | B21: 145286.25 | D21: Monitor Stand | E21: 75238.95 | F21: 185238.95 | G21: Telangana | H21: 156655.4 | I21: 428675.4 | L21: 2718029.7 | M21: 7725669.7
A22: Grand Total | B22: 2718029.7 | D22: Notebook Pack of 5 | E22: 25852.85 | F22: 69412.85 | G22: Uttar Pradesh | H22: 54039.15 | I22: 141969.15 | L22: Average of net_sales
D23: Office Chair | E23: 395291.45 | F23: 1284291.5 | G23: West Bengal | H23: 131286.05 | I23: 365676.05 | L23: 6438.0581
D24: Power Bank 10000mAh | E24: 104349.4 | F24: 299549.4 | G24: Grand Total | H24: 2718029.7 | I24: 7725669.7
D25: Stapler | E25: 15331 | F25: 36091
D26: Study Table | E26: 338391.3 | F26: 1031391.3
D27: Track Pants | E27: 106799.55 | F27: 229649.55 | I27: Row Labels | J27: Sum of profit
D28: USB Flash Drive 64GB | E28: 41308.85 | F28: 108508.85 | I28: Central | J28: 447798.5
D29: Webcam HD | E29: 116351.2 | F29: 339651.2 | I29: East | J29: 403586.6
D30: Whiteboard Marker Set | E30: 20164 | F30: 53064 | I30: North | J30: 551167.7
D31: Wireless Mouse | E31: 51295 | F31: 163345 | I31: South | J31: 537759
D32: Grand Total | E32: 2718029.7 | F32: 7725669.7 | I32: West | J32: 777717.9
I33: Grand Total | J33: 2718029.7
A51: Count of Order ID | B51: Column Labels
A52: Row Labels | B52: Cancelled | C52: Delivered | D52: Pending | E52: Returned | F52: Grand Total
A53: Bihar | B53: 4 | C53: 48 | D53: 3 | E53: 7 | F53: 62
A54: Chandigarh | B54: 6 | C54: 65 | D54: 2 | E54: 4 | F54: 77
A55: Delhi | B55: 7 | C55: 65 | D55: 3 | E55: 7 | F55: 82
A56: Gujarat | B56: 15 | C56: 202 | D56: 5 | E56: 13 | F56: 235
A57: Karnataka | B57: 2 | C57: 36 | F57: 38
...

Sheet Dashboard

Sheet Monthly_Targets_2025
A1: Region | B1: Jan | C1: Feb | D1: Mar | E1: Apr | F1: May | G1: Jun | H1: Jul | I1: Aug | J1: Sep | K1: Oct | L1: Nov | M1: Dec
A2: West | B2: 150000 | C2: 260000 | D2: 375000 | E2: 210000 | F2: 185000 | G2: 210000 | H2: 240000 | I2: 160000 | J2: 190000 | K2: 275000 | L2: 280000 | M2: 385000
A3: North | B3: 255000 | C3: 160000 | D3: 200000 | E3: 360000 | F3: 210000 | G3: 300000 | H3: 360000 | I3: 235000 | J3: 185000 | K3: 280000 | L3: 305000 | M3: 325000
A4: South | B4: 305000 | C4: 365000 | D4: 375000 | E4: 190000 | F4: 250000 | G4: 390000 | H4: 390000 | I4: 395000 | J4: 275000 | K4: 310000 | L4: 380000 | M4: 385000
A5: East | B5: 270000 | C5: 190000 | D5: 185000 | E5: 180000 | F5: 155000 | G5: 190000 | H5: 195000 | I5: 260000 | J5: 310000 | K5: 150000 | L5: 395000 | M5: 365000
A6: Central | B6: 225000 | C6: 165000 | D6: 365000 | E6: 255000 | F6: 285000 | G6: 340000 | H6: 385000 | I6: 150000 | J6: 285000 | K6: 300000 | L6: 240000 | M6: 240000
